<?xml version="1.0" encoding="utf-8"?>
<!-- This URDF was automatically created by SolidWorks to URDF Exporter! Originally created by Stephen Brawner (brawner@gmail.com) 
     Commit Version: 1.5.1-0-g916b5db  Build Version: 1.5.7152.31018
     For more information, please see http://wiki.ros.org/sw_urdf_exporter -->
<robot
  name="robot">
  <link
    name="base_link">
    <inertial>
      <origin
        xyz="1.21320825855915E-17 -8.65073877803282E-20 0.006"
        rpy="0 0 0" />
      <mass
        value="0.699812398023691" />
      <inertia
        ixx="0.00319439358076906"
        ixy="-1.05879118406788E-19"
        ixz="-7.74183984731718E-21"
        iyy="0.00687705018768615"
        iyz="9.68378407216369E-19"
        izz="0.0100546482709026" />
    </inertial>
    <visual>
      <origin
        xyz="0 0 0"
        rpy="0 0 0" />
      <geometry>
        <mesh
          filename="package://robot/meshes/base_link.STL" />
      </geometry>
      <material
        name="">
        <color
          rgba="0.0980392156862745 0.0980392156862745 0.0980392156862745 1" />
      </material>
    </visual>
    <collision>
      <origin
        xyz="0 0 0"
        rpy="0 0 0" />
      <geometry>
        <mesh
          filename="package://robot/meshes/base_link.STL" />
      </geometry>
    </collision>
  </link>
  <link
    name="Link_0">
    <inertial>
      <origin
        xyz="1.45774148422336E-06 -0.00427622104434238 0.0788670597889417"
        rpy="0 0 0" />
      <mass
        value="0.88340905364341" />
      <inertia
        ixx="0.0037870391075153"
        ixy="-6.32343925976529E-08"
        ixz="5.11803228852615E-08"
        iyy="0.00407855138323904"
        iyz="-0.000191161132544313"
        izz="0.00446295424659251" />
    </inertial>
    <visual>
      <origin
        xyz="0 0 0"
        rpy="0 0 0" />
      <geometry>
        <mesh
          filename="package://robot/meshes/Link_0.STL" />
      </geometry>
      <material
        name="">
        <color
          rgba="0.792156862745098 0.819607843137255 0.933333333333333 1" />
      </material>
    </visual>
    <collision>
      <origin
        xyz="0 0 0"
        rpy="0 0 0" />
      <geometry>
        <mesh
          filename="package://robot/meshes/Link_0.STL" />
      </geometry>
    </collision>
  </link>
  <joint
    name="Joint_0"
    type="fixed">
    <origin
      xyz="0 0 0.012"
      rpy="0 0 3.1416" />
    <parent
      link="base_link" />
    <child
      link="Link_0" />
    <axis
      xyz="0 0 0" />
  </joint>
  <link
    name="Link_1">
    <inertial>
      <origin
        xyz="6.22184642160937E-05 -0.0650398405116139 0.0829876435373044"
        rpy="0 0 0" />
      <mass
        value="0.597465762898965" />
      <inertia
        ixx="0.00345999864180008"
        ixy="2.11239130676265E-06"
        ixz="-1.08552992986325E-06"
        iyy="0.0024416733218569"
        iyz="0.0005220262651637"
        izz="0.00326944956816068" />
    </inertial>
    <visual>
      <origin
        xyz="0 0 0"
        rpy="0 0 0" />
      <geometry>
        <mesh
          filename="package://robot/meshes/Link_1.STL" />
      </geometry>
      <material
        name="">
        <color
          rgba="0.792156862745098 0.819607843137255 0.933333333333333 1" />
      </material>
    </visual>
    <collision>
      <origin
        xyz="0 0 0"
        rpy="0 0 0" />
      <geometry>
        <mesh
          filename="package://robot/meshes/Link_1.STL" />
      </geometry>
    </collision>
  </link>
  <joint
    name="Joint_1"
    type="continuous">
    <origin
      xyz="0 0 0.18443"
      rpy="0 0 -0.13381" />
    <parent
      link="Link_0" />
    <child
      link="Link_1" />
    <axis
      xyz="0 0 1" />
    <limit
      lower="0"
      upper="0"
      effort="0"
      velocity="0" />
  </joint>
  <link
    name="Link_2">
    <inertial>
      <origin
        xyz="0.00134485274787528 -0.128717701017697 0.160867386542986"
        rpy="0 0 0" />
      <mass
        value="0.929159054625162" />
      <inertia
        ixx="0.00320823920259881"
        ixy="-1.35631231568004E-07"
        ixz="-3.85045874100545E-06"
        iyy="0.00265580306712729"
        iyz="-0.000100375628699397"
        izz="0.00266571607277529" />
    </inertial>
    <visual>
      <origin
        xyz="0 0 0"
        rpy="0 0 0" />
      <geometry>
        <mesh
          filename="package://robot/meshes/Link_2.STL" />
      </geometry>
      <material
        name="">
        <color
          rgba="0.792156862745098 0.819607843137255 0.933333333333333 1" />
      </material>
    </visual>
    <collision>
      <origin
        xyz="0 0 0"
        rpy="0 0 0" />
      <geometry>
        <mesh
          filename="package://robot/meshes/Link_2.STL" />
      </geometry>
    </collision>
  </link>
  <joint
    name="Joint_2"
    type="continuous">
    <origin
      xyz="0.00017522 -0.12162 0.095568"
      rpy="0.00045409 -0.30533 -6.9868E-05" />
    <parent
      link="Link_1" />
    <child
      link="Link_2" />
    <axis
      xyz="0.0014407 -1 0" />
    <limit
      lower="0"
      upper="0"
      effort="0"
      velocity="0" />
  </joint>
  <link
    name="Link_3">
    <inertial>
      <origin
        xyz="0.00120771076428626 0.0539172581071677 0.178976869308194"
        rpy="0 0 0" />
      <mass
        value="0.803150335900571" />
      <inertia
        ixx="0.00270458546599755"
        ixy="1.60745380689648E-06"
        ixz="-3.81500108563491E-06"
        iyy="0.00209383755862316"
        iyz="0.000131370312331567"
        izz="0.002184375360029" />
    </inertial>
    <visual>
      <origin
        xyz="0 0 0"
        rpy="0 0 0" />
      <geometry>
        <mesh
          filename="package://robot/meshes/Link_3.STL" />
      </geometry>
      <material
        name="">
        <color
          rgba="0.792156862745098 0.819607843137255 0.933333333333333 1" />
      </material>
    </visual>
    <collision>
      <origin
        xyz="0 0 0"
        rpy="0 0 0" />
      <geometry>
        <mesh
          filename="package://robot/meshes/Link_3.STL" />
      </geometry>
    </collision>
  </link>
  <joint
    name="Joint_3"
    type="continuous">
    <origin
      xyz="0.00222521674691062 0 0.309992013445751"
      rpy="-0.000434921820504719 0.293183077036062 -6.42165046319621E-05" />
    <parent
      link="Link_2" />
    <child
      link="Link_3" />
    <axis
      xyz="0.00144069687900125 -0.999998962195713 0" />
    <limit
      lower="0"
      upper="0"
      effort="0"
      velocity="0" />
  </joint>
  <link
    name="Link_4">
    <inertial>
      <origin
        xyz="0.000359208754147869 -0.0684998573002637 0.0366860909640123"
        rpy="0 0 0" />
      <mass
        value="0.286971915713618" />
      <inertia
        ixx="0.000828640635214267"
        ixy="1.35924993163465E-06"
        ixz="-2.2970662177991E-06"
        iyy="0.000726145495651607"
        iyz="0.000173192471972522"
        izz="0.000543678533337081" />
    </inertial>
    <visual>
      <origin
        xyz="0 0 0"
        rpy="0 0 0" />
      <geometry>
        <mesh
          filename="package://robot/meshes/Link_4.STL" />
      </geometry>
      <material
        name="">
        <color
          rgba="0.792156862745098 0.819607843137255 0.933333333333333 1" />
      </material>
    </visual>
    <collision>
      <origin
        xyz="0 0 0"
        rpy="0 0 0" />
      <geometry>
        <mesh
          filename="package://robot/meshes/Link_4.STL" />
      </geometry>
    </collision>
  </link>
  <joint
    name="Joint_4"
    type="continuous">
    <origin
      xyz="0.0023197 -0.065602 0.30999"
      rpy="0 0.004971 0" />
    <parent
      link="Link_3" />
    <child
      link="Link_4" />
    <axis
      xyz="0.0014407 -1 0" />
    <limit
      lower="0"
      upper="0"
      effort="0"
      velocity="0" />
  </joint>
  <link
    name="Link_5">
    <inertial>
      <origin
        xyz="0.00378239646695921 -0.00233701451342877 0.0601240679145671"
        rpy="0 0 0" />
      <mass
        value="0.285365755979253" />
      <inertia
        ixx="0.000630498937647437"
        ixy="0.000191144855822565"
        ixz="-1.04125912684127E-05"
        iyy="0.000771007929254481"
        iyz="6.90460062027828E-06"
        izz="0.000829828222358698" />
    </inertial>
    <visual>
      <origin
        xyz="0 0 0"
        rpy="0 0 0" />
      <geometry>
        <mesh
          filename="package://robot/meshes/Link_5.STL" />
      </geometry>
      <material
        name="">
        <color
          rgba="0.792156862745098 0.819607843137255 0.933333333333333 1" />
      </material>
    </visual>
    <collision>
      <origin
        xyz="0 0 0"
        rpy="0 0 0" />
      <geometry>
        <mesh
          filename="package://robot/meshes/Link_5.STL" />
      </geometry>
    </collision>
  </link>
  <joint
    name="Joint_5"
    type="continuous">
    <origin
      xyz="0.00100383603243955 -0.0856181626338182 0.122659101891894"
      rpy="-0.00365492551536334 -0.001006271156386 -0.534443961021636" />
    <parent
      link="Link_4" />
    <child
      link="Link_5" />
    <axis
      xyz="0.00717811853827576 1.0341503609013E-05 0.999974236921784" />
    <limit
      lower="0"
      upper="0"
      effort="0"
      velocity="0" />
  </joint>
  <link
    name="Link_6">
    <inertial>
      <origin
        xyz="0.04864 -2.7756E-17 -2.2204E-16"
        rpy="0 0 0" />
      <mass
        value="0.093174" />
      <inertia
        ixx="7.7434E-05"
        ixy="2.9646E-20"
        ixz="2.7423E-19"
        iyy="4.4544E-05"
        iyz="-4.5604E-08"
        izz="4.391E-05" />
    </inertial>
    <visual>
      <origin
        xyz="0 0 0"
        rpy="0 0 0" />
      <geometry>
        <mesh
          filename="package://robot/meshes/Link_6.STL" />
      </geometry>
      <material
        name="">
        <color
          rgba="0.34902 0.34902 0.34902 1" />
      </material>
    </visual>
    <collision>
      <origin
        xyz="0 0 0"
        rpy="0 0 0" />
      <geometry>
        <mesh
          filename="package://robot/meshes/Link_6.STL" />
      </geometry>
    </collision>
  </link>
  <joint
    name="Joint_6"
    type="continuous">
    <origin
      xyz="0.035368 -0.024347 0.068086"
      rpy="-2.9035 0.00588 -0.60944" />
    <parent
      link="Link_5" />
    <child
      link="Link_6" />
    <axis
      xyz="1 0 0" />
    <limit
      lower="0"
      upper="0"
      effort="0"
      velocity="0" />
  </joint>
</robot>